<?xml version="1.0"?>
<!-- PhantomX Pincher gripper URDF-->
<robot xmlns:xacro="http://ros.org/wiki/xacro">
    
    <!-- gripper joint -->
    <!-- Finger 1 --> 
    <joint name="gripper_joint" type="prismatic">
      <origin xyz="0.070 0 0" rpy="0 0 0"/>
      <axis xyz="0 1 0"/>
      <limit effort="3" velocity="0.05" lower="0.002" upper="0.032"/>
      <parent link="arm_wrist_flex_link"/>
      <child link="gripper_active_link"/>
      <dynamics friction="0.13"/>
    </joint> 
    
    <pincher_finger name="gripper_active" color="${color}" >
      <origin xyz="0 0 0" rpy="0 0 0"/>
    </pincher_finger>

    <transmission name="gripper_joint_transmission">
      <type>transmission_interface/SimpleTransmission</type>
      <joint name="gripper_joint">
        <hardwareInterface>hardware_interface/EffortJointInterface</hardwareInterface>
      </joint>
      <actuator name="gripper_joint_actuator">
        <hardwareInterface>EffortJointInterface</hardwareInterface>
        <mechanicalReduction>1</mechanicalReduction>
      </actuator>
    </transmission>
     
    <!-- Finger 2 --> 
    <!-- Note: currently static but should be a Mimic of Finger 1 -->
    <!--joint name="gripper2_joint" type="fixed">
      <origin xyz="0.070 -0.016 0" rpy="0 0 0"/>
      <parent link="arm_wrist_flex_link"/>
      <child link="gripper_active2_link"/>
    </joint-->  
    
    <pincher_finger name="gripper_active2" color="${color}" >
      <origin xyz="0 0 0" rpy="${M_PI} 0 0"/>
    </pincher_finger>
      
    <!-- Using Mimic -->
    <!-- gripper 2 joint -->
    <!--  TODO: Test Mimic -->
    <joint name="gripper2_joint" type="prismatic">
      <origin xyz="0.070 0 0" rpy="0 0 0"/>
      <axis xyz="0 1 0"/>
      <limit effort="3" velocity="0.05" lower="-0.032" upper="-0.002"/>
      <parent link="arm_wrist_flex_link"/>
      <child link="gripper_active2_link"/>
      <!--mimic joint="gripper_joint" multiplier="-1"  offset = "0"/-->
      <dynamics friction="0.13"/>
    </joint> 

    <transmission name="gripper2_joint_transmission">
      <type>transmission_interface/SimpleTransmission</type>
      <joint name="gripper2_joint">
        <hardwareInterface>hardware_interface/EffortJointInterface</hardwareInterface>
      </joint>
      <actuator name="gripper2_joint_actuator">
        <hardwareInterface>EffortJointInterface</hardwareInterface>
        <mechanicalReduction>1</mechanicalReduction>
      </actuator>
    </transmission>
 
</robot>
